Workbook

Sheet Executive Summary
B2: PRISM TECHNOLOGIES INC.
B3: Institutional Cross-Venue Prediction Market Smart Order Router (SOR)
B4: 5-Year Pro-Forma Financial Model & CFO Business Plan (Series Seed / Series A)
B6: Y1 ARR | D6: Y3 ARR | F6: Y5 ARR | H6: Y3 EBITDA MARGIN | J6: Y3 GROSS MARGIN
B7: ='5-Year Pro-Forma'!C26 | D7: ='5-Year Pro-Forma'!E26 | F7: ='5-Year Pro-Forma'!G26 | H7: ='5-Year Pro-Forma'!E46 | J7: ='5-Year Pro-Forma'!E35
B10: EXECUTIVE FINANCIAL DASHBOARD (5-YEAR PRO-FORMA)
B11: Financial Metric | C11: Year 1 (Seed) | D11: Year 2 (Expansion) | E11: Year 3 (Scale) | F11: Year 4 (Institutional) | G11: Year 5 (Category King)
B12: Active Trading Desks | C12: ='5-Year Pro-Forma'!C12 | D12: ='5-Year Pro-Forma'!D12 | E12: ='5-Year Pro-Forma'!E12 | F12: ='5-Year Pro-Forma'!F12 | G12: ='5-Year Pro-Forma'!G12
B13: Monthly Routed Notional ($M) | C13: ='5-Year Pro-Forma'!C13 | D13: ='5-Year Pro-Forma'!D13 | E13: ='5-Year Pro-Forma'!E13 | F13: ='5-Year Pro-Forma'!F13 | G13: ='5-Year Pro-Forma'!G13
B14: Annual Routed Notional ($M) | C14: ='5-Year Pro-Forma'!C14 | D14: ='5-Year Pro-Forma'!D14 | E14: ='5-Year Pro-Forma'!E14 | F14: ='5-Year Pro-Forma'!F14 | G14: ='5-Year Pro-Forma'!G14
B16: SaaS Subscription Revenue | C16: ='5-Year Pro-Forma'!C21 | D16: ='5-Year Pro-Forma'!D21 | E16: ='5-Year Pro-Forma'!E21 | F16: ='5-Year Pro-Forma'!F21 | G16: ='5-Year Pro-Forma'!G21
B17: Volume Routing Take-Rate | C17: ='5-Year Pro-Forma'!C22 | D17: ='5-Year Pro-Forma'!D22 | E17: ='5-Year Pro-Forma'!E22 | F17: ='5-Year Pro-Forma'!F22 | G17: ='5-Year Pro-Forma'!G22
B18: Premium Data & SLA Feeds | C18: ='5-Year Pro-Forma'!C23 | D18: ='5-Year Pro-Forma'!D23 | E18: ='5-Year Pro-Forma'!E23 | F18: ='5-Year Pro-Forma'!F23 | G18: ='5-Year Pro-Forma'!G23
B19: Gross Revenue | C19: ='5-Year Pro-Forma'!C24 | D19: ='5-Year Pro-Forma'!D24 | E19: ='5-Year Pro-Forma'!E24 | F19: ='5-Year Pro-Forma'!F24 | G19: ='5-Year Pro-Forma'!G24
B20: Less: Upfront Prepay Discounts (15%) | C20: ='5-Year Pro-Forma'!C25 | D20: ='5-Year Pro-Forma'!D25 | E20: ='5-Year Pro-Forma'!E25 | F20: ='5-Year Pro-Forma'!F25 | G20: ='5-Year Pro-Forma'!G25
B21: Net Recognized Revenue | C21: ='5-Year Pro-Forma'!C26 | D21: ='5-Year Pro-Forma'!D26 | E21: ='5-Year Pro-Forma'!E26 | F21: ='5-Year Pro-Forma'!F26 | G21: ='5-Year Pro-Forma'!G26
B23: Cost of Goods Sold (COGS) | C23: ='5-Year Pro-Forma'!C33 | D23: ='5-Year Pro-Forma'!D33 | E23: ='5-Year Pro-Forma'!E33 | F23: ='5-Year Pro-Forma'!F33 | G23: ='5-Year Pro-Forma'!G33
B24: Gross Profit | C24: ='5-Year Pro-Forma'!C34 | D24: ='5-Year Pro-Forma'!D34 | E24: ='5-Year Pro-Forma'!E34 | F24: ='5-Year Pro-Forma'!F34 | G24: ='5-Year Pro-Forma'!G34
B25: Gross Margin % | C25: ='5-Year Pro-Forma'!C35 | D25: ='5-Year Pro-Forma'!D35 | E25: ='5-Year Pro-Forma'!E35 | F25: ='5-Year Pro-Forma'!F35 | G25: ='5-Year Pro-Forma'!G35
B27: Research & Development (R&D) | C27: ='5-Year Pro-Forma'!C38 | D27: ='5-Year Pro-Forma'!D38 | E27: ='5-Year Pro-Forma'!E38 | F27: ='5-Year Pro-Forma'!F38 | G27: ='5-Year Pro-Forma'!G38
B28: Sales & Trading BD (S&M) | C28: ='5-Year Pro-Forma'!C39 | D28: ='5-Year Pro-Forma'!D39 | E28: ='5-Year Pro-Forma'!E39 | F28: ='5-Year Pro-Forma'!F39 | G28: ='5-Year Pro-Forma'!G39
B29: General & Administrative (G&A) | C29: ='5-Year Pro-Forma'!C40 | D29: ='5-Year Pro-Forma'!D40 | E29: ='5-Year Pro-Forma'!E40 | F29: ='5-Year Pro-Forma'!F40 | G29: ='5-Year Pro-Forma'!G40
B30: Total Operating Expenses | C30: ='5-Year Pro-Forma'!C42 | D30: ='5-Year Pro-Forma'!D42 | E30: ='5-Year Pro-Forma'!E42 | F30: ='5-Year Pro-Forma'!F42 | G30: ='5-Year Pro-Forma'!G42
B32: EBITDA (Operating Profit) | C32: ='5-Year Pro-Forma'!C45 | D32: ='5-Year Pro-Forma'!D45 | E32: ='5-Year Pro-Forma'!E45 | F32: ='5-Year Pro-Forma'!F45 | G32: ='5-Year Pro-Forma'!G45
B33: EBITDA Margin % | C33: ='5-Year Pro-Forma'!C46 | D33: ='5-Year Pro-Forma'!D46 | E33: ='5-Year Pro-Forma'!E46 | F33: ='5-Year Pro-Forma'!F46 | G33: ='5-Year Pro-Forma'!G46
B34: Operating Income (EBIT) | C34: ='5-Year Pro-Forma'!C48 | D34: ='5-Year Pro-Forma'!D48 | E34: ='5-Year Pro-Forma'!E48 | F34: ='5-Year Pro-Forma'!F48 | G34: ='5-Year Pro-Forma'!G48
B35: Net Income (After Tax) | C35: ='5-Year Pro-Forma'!C52 | D35: ='5-Year Pro-Forma'!D52 | E35: ='5-Year Pro-Forma'!E52 | F35: ='5-Year Pro-Forma'!F52 | G35: ='5-Year Pro-Forma'!G52
B36: Net Income Margin % | C36: ='5-Year Pro-Forma'!C53 | D36: ='5-Year Pro-Forma'!D53 | E36: ='5-Year Pro-Forma'!E53 | F36: ='5-Year Pro-Forma'!F53 | G36: ='5-Year Pro-Forma'!G53
B38: Implied Valuation (25x ARR Multiple) | C38: ='Valuation & Returns'!C21 | D38: ='Valuation & Returns'!D21 | E38: ='Valuation & Returns'!E21 | F38: ='Valuation & Returns'!F21 | G38: ='Valuation & Returns'!G21

Sheet Model Assumptions
B2: PRISM FINANCIAL ARCHITECTURE — MASTER ASSUMPTIONS
B3: Dynamic Drivers Governing Unit Economics, Revenue Take-Rates, Capacity, and Headcount
B5: 1. MARKET SIZE & MACRO PREDICTION ADOPTION (TAM / SAM / SOM)
B6: Driver / Assumption | C6: Value | D6: Unit | E6: Strategic Rationale / Grounding
B7: Total Global Event Derivatives Market Notional (Y1) | C7: 12000 | D7: $M | E7: Estimated 2026 combined Polymarket + Kalshi + ForecastEx volume
B8: Total Global Event Derivatives Market Notional (Y3) | C8: 85000 | D8: $M | E8: Expansion into macro indices, rates, and corporate earnings
B9: Total Global Event Derivatives Market Notional (Y5) | C9: 320000 | D9: $M | E9: Institutional scale capturing 0.2% of global macro hedging
B10: PRISM Share of Institutional Routed Flow (Y1) | C10: 0.008 | D10: % | E10: Capturing 0.8% of market volume in Seed year ($96M/yr)
B11: PRISM Share of Institutional Routed Flow (Y3) | C11: 0.052 | D11: % | E11: Capturing 5.2% of total market volume ($4.42B/yr)
B12: PRISM Share of Institutional Routed Flow (Y5) | C12: 0.12 | D12: % | E12: Capturing 12.0% as category king execution standard ($38.4B/yr)
B14: 2. SUBSCRIPTION PRICING TIERS & ANNUAL CONTRACT VALUE (ACV)
B15: Pricing Tier | C15: Monthly Fee | D15: Annual ACV | E15: Target Profile & Inclusions
B16: Tier 1: Core Quant API | C16: 2500 | D16: $ | E16: Systematic algo bots, 100 req/sec, standard REST/WebSocket
B17: Tier 2: Institutional Desk (Core Flagship) | C17: 12000 | D17: $ | E17: Multi-seat terminal, Parity Radar, Oracle Conflict Guard, 99.95% SLA
B18: Tier 3: Prime Direct (Enterprise) | C18: 35000 | D18: $ | E18: Dedicated VPC instance, custom Iceberg/TWAP algos, FIX drop-copy
B19: Tier 4: Sovereign Co-Location (Secaucus NY4) | C19: 65000 | D19: $ | E19: Direct Equinix NY4 10Gbps cross-connect, sub-0.5ms FPGA path
B20: Annual Upfront Prepay Discount | C20: 0.15 | D20: % | E20: 15% discount for 12-month upfront cash payment (creates negative working capital)
B21: Expected % of Clients Choosing Annual Prepay | C21: 0.45 | D21: % | E21: Funds taking advantage of annual budget allocation discounts
B23: 3. VARIABLE ROUTING TAKE-RATE (SOR BASIS POINTS)
B24: Parameter | C24: Value | D24: Unit | E24: Economic Mechanism
B25: Standard Volume Routing Take-Rate | C25: 0.00015 | D25: % | E25: 1.5 bps (0.015%) charged on net notional executed through SOR
B26: Average Slippage Saved per Client Order | C26: 0.0296 | D26: % | E26: 296 bps saved vs single-venue execution (clients retain 95% of alpha)
B27: Client Value-to-Fee Ratio | C27: 19.7 | D27: x | E27: Clients save $19.70 for every $1.00 paid to PRISM in routing fees
B29: 4. CUSTOMER FUNNEL, RETENTION & SALES EFFICIENCY
B30: Funnel Metric | C30: Value | D30: Unit | E30: Industry Benchmark Comparison
B31: Tier 2 CAC (Institutional Desk) | C31: 22000 | D31: $ | E31: Technical sales engineer salary, compliance review, POC demo period
B32: Tier 3 CAC (Prime Direct) | C32: 65000 | D32: $ | E32: Enterprise procurement, on-premise security review, legal review
B33: Sales Cycle Duration (Tier 2) | C33: 45 | D33: Days | E33: Rapid trial-to-production deployment timeline
B34: Annual Gross Logo Churn Rate | C34: 0.05 | D34: % | E34: 5% annual churn (OEMS workflow integration creates high stickiness)
B35: Net Revenue Retention (NRR) | C35: 1.28 | D35: % | E35: 128% NRR driven by funds adding seats and increasing routed volume
B37: 5. INFRASTRUCTURE & COGS DRIVERS (FIXED & VARIABLE)
B38: Cost Component | C38: Monthly Cost | D38: Unit | E38: Vendor / Allocation Details
B39: Equinix NY4 Secaucus Cabinet Base Lease | C39: 6500 | D39: $ | E39: 1U-4U rack space, redundant PDU, Secaucus datacenter
B40: NY4 Cross-Connect per 10 Active Clients | C40: 1200 | D40: $ | E40: Direct low-latency fiber cross-connects to exchange matching engines
B41: Enterprise L2 RPC Nodes (Polygon/Arbitrum) | C41: 2200 | D41: $ | E41: Dedicated high-throughput Alchemy/QuickNode endpoints
B42: AWS/GCP Serverless Engine Base | C42: 1800 | D42: $ | E42: Database clusters, Redis low-latency cache, API gateways
B43: Cloud Variable Cost per $1M Routed | C43: 12 | D43: $ | E43: Elastic serverless execution scaling per order million
B44: FIPS 140-2 Level 3 HSM Hardware Security | C44: 1500 | D44: $ | E44: Dedicated cryptographic key validation hardware
B45: Real-Time L2 Market Data Streaming Relays | C45: 2000 | D45: $ | E45: WebSocket distribution clusters
B47: 6. PERSONNEL HEADCOUNT & SALARY ASSUMPTIONS
...

Sheet 5-Year Pro-Forma
B2: PRISM 5-YEAR PRO-FORMA INCOME STATEMENT (ANNUAL)
B3: Forecast of Revenues, COGS, OpEx, EBITDA, and Net Income (2026 - 2030)
B5: Line Item / Operational Metric | C5: Year 1 (Seed) | D5: Year 2 (Expansion) | E5: Year 3 (Scale) | F5: Year 4 (Institutional) | G5: Year 5 (Category King)
B7: KEY REVENUE DRIVERS
B8: Tier 1 Clients (Core API @ $2.5k/mo) | C8: 4 | D8: 15 | E8: 35 | F8: 60 | G8: 95
B9: Tier 2 Clients (Institutional Desk @ $12k/mo) | C9: 7 | D9: 28 | E9: 75 | F9: 140 | G9: 220
B10: Tier 3 Clients (Prime Direct @ $35k/mo) | C10: 1 | D10: 5 | E10: 18 | F10: 38 | G10: 65
B11: Tier 4 Clients (Sovereign Co-Lo @ $65k/mo) | C11: 0 | D11: 0 | E11: 2 | F11: 6 | G11: 12
B12: Total Active Institutional Desks | C12: =SUM(C8:C11) | D12: =SUM(D8:D11) | E12: =SUM(E8:E11) | F12: =SUM(F8:F11) | G12: =SUM(G8:G11)
B13: Average Monthly Routed Volume per Desk ($M) | C13: 6.7 | D13: 7.3 | E13: 10.8 | F13: 14.2 | G13: 17.5
B14: Annual Routed Notional Volume ($M) | C14: =C12*C13*12 | D14: =D12*D13*12 | E14: =E12*E13*12 | F14: =F12*F13*12 | G14: =G12*G13*12
B16: REVENUE STREAMS
B17: Tier 1: Core Quant API Revenue | C17: =C8*'Model Assumptions'!C15*12 | D17: =D8*'Model Assumptions'!C15*12 | E17: =E8*'Model Assumptions'!C15*12 | F17: =F8*'Model Assumptions'!C15*12 | G17: =G8*'Model Assumptions'!C15*12
B18: Tier 2: Institutional Desk Revenue | C18: =C9*'Model Assumptions'!C16*12 | D18: =D9*'Model Assumptions'!C16*12 | E18: =E9*'Model Assumptions'!C16*12 | F18: =F9*'Model Assumptions'!C16*12 | G18: =G9*'Model Assumptions'!C16*12
B19: Tier 3: Prime Direct Revenue | C19: =C10*'Model Assumptions'!C17*12 | D19: =D10*'Model Assumptions'!C17*12 | E19: =E10*'Model Assumptions'!C17*12 | F19: =F10*'Model Assumptions'!C17*12 | G19: =G10*'Model Assumptions'!C17*12
B20: Tier 4: Sovereign Co-Lo Revenue | C20: =C11*'Model Assumptions'!C18*12 | D20: =D11*'Model Assumptions'!C18*12 | E20: =E11*'Model Assumptions'!C18*12 | F20: =F11*'Model Assumptions'!C18*12 | G20: =G11*'Model Assumptions'!C18*12
B21: Total SaaS Subscription Revenue (ARR) | C21: =SUM(C17:C20) | D21: =SUM(D17:D20) | E21: =SUM(E17:E20) | F21: =SUM(F17:F20) | G21: =SUM(G17:G20)
B22: Volume Routing Take-Rate (1.5 bps) | C22: =C14*1000000*'Model Assumptions'!C24 | D22: =D14*1000000*'Model Assumptions'!C24 | E22: =E14*1000000*'Model Assumptions'!C24 | F22: =F14*1000000*'Model Assumptions'!C24 | G22: =G14*1000000*'Model Assumptions'!C24
B23: Premium Data & Legal Oracle Feeds | C23: 75000 | D23: 360000 | E23: 1100000 | F23: 2400000 | G23: 4200000
B24: Total Gross Contracted Revenue | C24: =SUM(C21:C23) | D24: =SUM(D21:D23) | E24: =SUM(E21:E23) | F24: =SUM(F21:F23) | G24: =SUM(G21:G23)
B25: Less: Annual Prepay Cash Discounts | C25: =-C21*'Model Assumptions'!C19*'Model Assumptions'!C20 | D25: =-D21*'Model Assumptions'!C19*'Model Assumptions'!C20 | E25: =-E21*'Model Assumptions'!C19*'Model Assumptions'!C20 | F25: =-F21*'Model Assumptions'!C19*'Model Assumptions'!C20 | G25: =-G21*'Model Assumptions'!C19*'Model Assumptions'!C20
B26: NET RECOGNIZED REVENUE | C26: =C24+C25 | D26: =D24+D25 | E26: =E24+E25 | F26: =F24+F25 | G26: =G24+G25
B28: COST OF GOODS SOLD (COGS)
B29: Equinix NY4 Co-Location & Cross-Connects | C29: =('Model Assumptions'!C36*12)+(C12*'Model Assumptions'!C37*12/10) | D29: =('Model Assumptions'!C36*12)+(D12*'Model Assumptions'!C37*12/10) | E29: =('Model Assumptions'!C36*12)+(E12*'Model Assumptions'!C37*12/10) | F29: =('Model Assumptions'!C36*12)+(F12*'Model Assumptions'!C37*12/10) | G29: =('Model Assumptions'!C36*12)+(G12*'Model Assumptions'!C37*12/10)
B30: Enterprise RPC Nodes & L2 Gas Relayers | C30: ='Model Assumptions'!C38*12 | D30: ='Model Assumptions'!C38*12*1.8 | E30: ='Model Assumptions'!C38*12*3.2 | F30: ='Model Assumptions'!C38*12*5.5 | G30: ='Model Assumptions'!C38*12*8.0
B31: Cloud Compute, Redis & WebSocket Relays | C31: =('Model Assumptions'!C39*12)+(C14*'Model Assumptions'!C40) | D31: =('Model Assumptions'!C39*12)+(D14*'Model Assumptions'!C40) | E31: =('Model Assumptions'!C39*12)+(E14*'Model Assumptions'!C40) | F31: =('Model Assumptions'!C39*12)+(F14*'Model Assumptions'!C40) | G31: =('Model Assumptions'!C39*12)+(G14*'Model Assumptions'!C40)
B32: FIPS 140-2 Hardware HSM Cryptographic Security | C32: ='Model Assumptions'!C41*12 | D32: ='Model Assumptions'!C41*12*1.5 | E32: ='Model Assumptions'!C41*12*2.2 | F32: ='Model Assumptions'!C41*12*3.5 | G32: ='Model Assumptions'!C41*12*5.0
B33: TOTAL COST OF GOODS SOLD | C33: =SUM(C29:C32) | D33: =SUM(D29:D32) | E33: =SUM(E29:E32) | F33: =SUM(F29:F32) | G33: =SUM(G29:G32)
B34: GROSS PROFIT | C34: =C26-C33 | D34: =D26-D33 | E34: =E26-E33 | F34: =F26-F33 | G34: =G26-G33
B35: Gross Margin % | C35: =C34/C26 | D35: =D34/D26 | E35: =E34/E26 | F35: =F34/F26 | G35: =G34/G26
B37: OPERATING EXPENSES (OPEX)
B38: Research & Development (R&D / Low-Latency Engineering) | C38: 850000 | D38: 1800000 | E38: 3600000 | F38: 6200000 | G38: 9500000
B39: Sales & Marketing (Institutional Sales, Travel, Marketing) | C39: 220000 | D39: 650000 | E39: 1400000 | F39: 2800000 | G39: 4800000
B40: General & Administrative (Legal, Compliance, Audits, Insurance) | C40: 110000 | D40: 240000 | E40: 450000 | F40: 850000 | G40: 1400000
B41: Enterprise Tools, Security Audits & G&A Infrastructure | C41: 70000 | D41: 150000 | E41: 320000 | F41: 580000 | G41: 920000
B42: TOTAL OPERATING EXPENSES | C42: =SUM(C38:C41) | D42: =SUM(D38:D41) | E42: =SUM(E38:E41) | F42: =SUM(F38:F41) | G42: =SUM(G38:G41)
B44: PROFITABILITY & CASH GENERATION
B45: EBITDA (OPERATING PROFIT) | C45: =C34-C42 | D45: =D34-D42 | E45: =E34-E42 | F45: =F34-F42 | G45: =G34-G42
B46: EBITDA Margin % | C46: =C45/C26 | D46: =D45/D26 | E46: =E45/E26 | F46: =F45/F26 | G46: =G45/G26
B47: Less: Depreciation & Amortization (Servers/Hardware) | C47: 24000 | D47: 52000 | E47: 110000 | F47: 210000 | G47: 350000
...

Sheet Year 1 Monthly Cash Flow
B2: PRISM YEAR 1 MONTHLY CASH FLOW & RUNWAY MONITOR
B3: Demonstrating Capital Preservation, Upfront Float, and Net Burn Path from Seed Funding
B5: Cash Flow Line Item | C5: Month 1 | D5: Month 2 | E5: Month 3 | F5: Month 4 | G5: Month 5 | H5: Month 6 | I5: Month 7 | J5: Month 8 | K5: Month 9 | L5: Month 10 | M5: Month 11 | N5: Month 12
B6: Beginning Cash Balance | C6: 3500000 | D6: =C26 | E6: =D26 | F6: =E26 | G6: =F26 | H6: =G26 | I6: =H26 | J6: =I26 | K6: =J26 | ... N6: =M26
B8: CASH INFLOWS:
B9: Active Client Desks | C9: 1 | D9: 1 | E9: 2 | F9: 3 | G9: 4 | H9: 5 | I9: 6 | J9: 7 | K9: 8 | L9: 10 | M9: 11 | N9: 12
B10: Monthly Subscription Inflows | C10: =C9*'Model Assumptions'!C16 | D10: =D9*'Model Assumptions'!C16 | E10: =E9*'Model Assumptions'!C16 | F10: =F9*'Model Assumptions'!C16 | G10: =G9*'Model Assumptions'!C16 | H10: =H9*'Model Assumptions'!C16 | I10: =I9*'Model Assumptions'!C16 | J10: =J9*'Model Assumptions'!C16 | K10: =K9*'Model Assumptions'!C16 | L10: =L9*'Model Assumptions'!C16 | M10: =M9*'Model Assumptions'!C16 | N10: =N9*'Model Assumptions'!C16
B11: Annual Upfront Prepay Cash Float | C11: 122400 | D11: 0 | E11: 122400 | F11: 0 | G11: 122400 | H11: 122400 | I11: 0 | J11: 122400 | K11: 0 | L11: 122400 | M11: 122400 | N11: 122400
B12: Variable Volume Routing Fees | C12: 2500 | D12: 3200 | E12: 5400 | F12: 7800 | G12: 10500 | H12: 13200 | I12: 16800 | J12: 20400 | K12: 24500 | L12: 29000 | M12: 34000 | N12: 41000
B13: Treasury Yield (Cash Sweep @ 4.8%) | C13: =C6*0.048/12 | D13: =D6*0.048/12 | E13: =E6*0.048/12 | F13: =F6*0.048/12 | G13: =G6*0.048/12 | H13: =H6*0.048/12 | I13: =I6*0.048/12 | J13: =J6*0.048/12 | ... N13: =N6*0.048/12
B14: Total Monthly Cash Inflows | C14: =SUM(C10:C13) | D14: =SUM(D10:D13) | E14: =SUM(E10:E13) | F14: =SUM(F10:F13) | G14: =SUM(G10:G13) | H14: =SUM(H10:H13) | I14: =SUM(I10:I13) | J14: =SUM(J10:J13) | ... N14: =SUM(N10:N13)
B16: CASH OUTFLOWS:
B17: Infrastructure & Co-Location COGS | C17: 11200 | D17: 11200 | E17: 12400 | F17: 12400 | G17: 13600 | H17: 13600 | I17: 14800 | J17: 14800 | K17: 16000 | L17: 16000 | M17: 17200 | N17: 17200
B18: Engineering Payroll (4 Engineers) | C18: 70000 | D18: 70000 | E18: 70000 | F18: 70000 | G18: 70000 | H18: 70000 | I18: 70000 | J18: 70000 | K18: 70000 | L18: 70000 | M18: 70000 | N18: 70000
B19: Sales & Business Development | C19: 12000 | D19: 12000 | E19: 15000 | F19: 15000 | G19: 18000 | H19: 18000 | I19: 21000 | J19: 21000 | K19: 24000 | L19: 24000 | M19: 27000 | N19: 27000
B20: Legal, Compliance & Retainers | C20: 15000 | D20: 6000 | E20: 6000 | F20: 6000 | G20: 6000 | H20: 6000 | I20: 6000 | J20: 6000 | K20: 6000 | L20: 6000 | M20: 6000 | N20: 6000
B21: SaaS Tooling, Admin, Insurance | C21: 4500 | D21: 4500 | E21: 4800 | F21: 4800 | G21: 5200 | H21: 5200 | I21: 5600 | J21: 5600 | K21: 6000 | L21: 6000 | M21: 6500 | N21: 6500
B22: Total Monthly Cash Outflows | C22: =SUM(C17:C21) | D22: =SUM(D17:D21) | E22: =SUM(E17:E21) | F22: =SUM(F17:F21) | G22: =SUM(G17:G21) | H22: =SUM(H17:H21) | I22: =SUM(I17:I21) | J22: =SUM(J17:J21) | ... N22: =SUM(N17:N21)
B24: NET MONTHLY CASH FLOW | C24: =C14-C22 | D24: =D14-D22 | E24: =E14-E22 | F24: =F14-F22 | G24: =G14-G22 | H24: =H14-H22 | I24: =I14-I22 | J24: =J14-J22 | ... N24: =N14-N22
B26: ENDING CASH BALANCE | C26: =C6+C24 | D26: =D6+D24 | E26: =E6+E24 | F26: =F6+F24 | G26: =G6+G24 | H26: =H6+H24 | I26: =I6+I24 | J26: =J6+J24 | ... N26: =N6+N24
B27: Runway Remaining (Months at Gross Burn) | C27: =C26/C22 | D27: =D26/D22 | E27: =E26/E22 | F27: =F26/F22 | G27: =G26/G22 | H27: =H26/H22 | I27: =I26/I22 | J27: =J26/J22 | ... N27: =N26/N22

Sheet Valuation & Returns
B2: PRISM UNIT ECONOMICS & VENTURE VALUATION SENSITIVITY
B3: Enterprise Multiple Analysis, Exit Scenarios, and Cohort Return Metrics
B5: 1. COHORT UNIT ECONOMICS BY PRICING TIER
B6: Metric / Parameter | C6: Tier 1: Core API | D6: Tier 2: Inst. Desk | E6: Tier 3: Prime Direct | F6: Blended Average
B7: Annual Contract Value (ACV) | C7: 30000 | D7: 144000 | E7: 420000 | F7: 162000
B8: Customer Acquisition Cost (CAC) | C8: 12000 | D8: 22000 | E8: 65000 | F8: 28000
B9: Payback Period (Months) | C9: =(C8/C7)*12 | D9: =(D8/D7)*12 | E9: =(E8/E7)*12 | F9: =(F8/F7)*12
B10: Gross Margin Contribution % | C10: 0.92 | D10: 0.94 | E10: 0.96 | F10: 0.94
B11: Annual Churn Rate % | C11: 0.08 | D11: 0.04 | E11: 0.02 | F11: 0.045
B12: Customer Lifetime (Years) | C12: =1/C11 | D12: =1/D11 | E12: =1/E11 | F12: =1/F11
B13: Lifetime Value (LTV) | C13: =C7*C10*C12 | D13: =D7*D10*D12 | E13: =E7*E10*E12 | F13: =F7*F10*F12
B14: LTV / CAC Ratio | C14: =C13/C8 | D14: =D13/D8 | E14: =E13/E8 | F14: =F13/F8
B17: 2. VALUATION SENSITIVITY TABLE (ARR MULTIPLES vs FORWARD REVENUE)
B18: ARR Multiple | C18: Year 1 ARR | D18: Year 2 ARR | E18: Year 3 ARR | F18: Year 4 ARR | G18: Year 5 ARR
B19: 15x Forward ARR Multiple | C19: ='5-Year Pro-Forma'!C26*15.0 | D19: ='5-Year Pro-Forma'!D26*15.0 | E19: ='5-Year Pro-Forma'!E26*15.0 | F19: ='5-Year Pro-Forma'!F26*15.0 | G19: ='5-Year Pro-Forma'!G26*15.0
B20: 20x Forward ARR Multiple | C20: ='5-Year Pro-Forma'!C26*20.0 | D20: ='5-Year Pro-Forma'!D26*20.0 | E20: ='5-Year Pro-Forma'!E26*20.0 | F20: ='5-Year Pro-Forma'!F26*20.0 | G20: ='5-Year Pro-Forma'!G26*20.0
B21: 25x Forward ARR Multiple | C21: ='5-Year Pro-Forma'!C26*25.0 | D21: ='5-Year Pro-Forma'!D26*25.0 | E21: ='5-Year Pro-Forma'!E26*25.0 | F21: ='5-Year Pro-Forma'!F26*25.0 | G21: ='5-Year Pro-Forma'!G26*25.0
B22: 30x Forward ARR Multiple | C22: ='5-Year Pro-Forma'!C26*30.0 | D22: ='5-Year Pro-Forma'!D26*30.0 | E22: ='5-Year Pro-Forma'!E26*30.0 | F22: ='5-Year Pro-Forma'!F26*30.0 | G22: ='5-Year Pro-Forma'!G26*30.0
B23: 35x Forward ARR Multiple | C23: ='5-Year Pro-Forma'!C26*35.0 | D23: ='5-Year Pro-Forma'!D26*35.0 | E23: ='5-Year Pro-Forma'!E26*35.0 | F23: ='5-Year Pro-Forma'!F26*35.0 | G23: ='5-Year Pro-Forma'!G26*35.0
B26: 3. STRATEGIC M&A & EXIT BENCHMARKS
B27: Potential Acquirer | C27: Strategic Rationale | D27: Comparable Deal Benchmark | E27: Target Valuation Range
B28: Intercontinental Exchange (ICE / NYSE) | C28: Acquisition of primary cross-venue event derivative routing utility | D28: ICE acquired Ellie Mae ($11B) & SuperDerivatives ($350M) | E28: $450M - $850M
B29: Bloomberg LP / Tradebook | C29: Incorporation into 350k+ Bloomberg Terminals as native event execution engine | D29: Bloomberg acquisitions of EMS/OEMS utilities | E29: $300M - $600M
B30: CME Group | C30: Integration with CME Event Contracts to dominate institutional macro derivative flow | D30: CME acquired NEX Group ($5.5B) | E30: $500M - $1.2B
B31: Citadel Securities / Jane Street | C31: Internalization of high-value non-toxic institutional event flow | D31: Virtu acquired ITG ($1B) | E31: $350M - $750M
B32: Coinbase Institutional | C32: Expansion from crypto spot/perps into global regulated event prediction markets | D32: Coinbase acquired Tagomi ($100M+) | E32: $250M - $500M
